Workbook
Name CanYouRedo: 'Financial Statements'!$K$28:$M$28
Name CLASSEBITDA: 'Financial Statements'!$K$29:$M$29
Name company.name: Parms!$A$1
Name D.F.INTEREST: DebtSchedule!$K$18:$O$18
Name D.F.Interest.Expense: DebtSchedule!$K$18:$K$18
Name d.f.long.debt: DebtSchedule!$K$22:$O$22
Name D.F.LTDebt: DebtSchedule!$K$22:$K$22
Name d.f.short.debt\: DebtSchedule!$K$21:$O$21
Name D.F.STDebt: DebtSchedule!$K$21:$K$21
Name D.H.Interest.Expense: DebtSchedule!$G$18:$I$18
Name D.H.LTDebt: DebtSchedule!$G$22:$I$22
Name D.H.STDebt: DebtSchedule!$G$21:$I$21
Name dates.forecast: Parms!$J$1:$N$1
Name dates.hist: Parms!$G$1:$I$1
Name DCF.Debt: DebtSchedule!$I$9
Name DCF.Equity: 'Financial Statements'!$I$82
Name dcf.fcf.y5: 'DCF Model'!$K$24
Name DCF.Interest.Expense: DebtSchedule!$I$18
Name DCF.Pref.Stock: 'Financial Statements'!$I$78
Name DCF.Table: 'DCF Model'!$G$15:$K$24
Name dcf.terminal.ebitda: 'DCF Model'!$K$15
Name dcf.terminaldc: 'DCF Model'!$K$25
Name f.cash: 'Financial Statements'!$K$117:$O$117
Name f.cash.financing: 'Financial Statements'!$K$113:$O$113
Name f.cash.invest: 'Financial Statements'!$K$104:$O$104
Name f.cash.investment: 'Financial Statements'!$K$106:$O$106
Name F.cash.ops: 'Financial Statements'!$K$101:$O$101
Name F.COGS: 'Financial Statements'!$K$13:$O$13
Name F.delta.working.capital: 'DCF Model'!$G$21:$K$21
Name F.EBIT: 'Financial Statements'!$K$28:$O$28
Name f.equity: 'Financial Statements'!$K$82:$O$82
Name F.FIXED.COSTS: 'Financial Statements'!$K$26:$O$26
Name F.MARGIN: 'Financial Statements'!$K$15:$O$15
Name f.net.income: 'Financial Statements'!$K$37:$O$37
Name F.REV: 'Financial Statements'!$K$7:$O$7
Name goldman.fee: 'Transaction Summary'!$G$19
Name H.Amort.Exp: 'Financial Statements'!$G$25:$I$25
Name H.Capital: 'Financial Statements'!$G$84:$I$84
Name H.Cash: 'Financial Statements'!$G$117:$I$117
Name H.Cash.Financing: 'Financial Statements'!$H$113:$I$113
Name H.Cash.From.Ops: 'Financial Statements'!$H$101:$I$101
Name H.Cash.Investment: 'Financial Statements'!$H$106:$I$106
Name H.COGS: 'Financial Statements'!$G$13:$I$13
Name H.Depr.Exp: 'Financial Statements'!$G$24:$I$24
Name H.EBIT: 'Financial Statements'!$G$28:$I$28
Name H.Fixed.Costs: 'Financial Statements'!$G$26:$I$26
Name H.Gross.Margin: 'Financial Statements'!$G$15:$I$15
Name H.Net.Income: 'Financial Statements'!$G$37:$I$37
Name H.Operating.Income: 'Financial Statements'!$G$28:$I$28
Name H.Revenues: 'Financial Statements'!$G$7:$I$7
Name H.Total.Assets: 'Financial Statements'!$G$60:$I$60
Name hist.amort: 'Financial Statements'!$I$25
Name hist.cash: 'Financial Statements'!$I$46
Name hist.depreciation: 'Financial Statements'!$I$24
Name hist.EBIT: 'Financial Statements'!$I$28
Name LBO.Discount.Factors: 'LBO Returns'!$G$19:$K$19
Name LBO.equity: 'Transaction Summary'!$N$7
Name LBO.Goodwill: 'Transaction Summary'!$G$24
Name LBO.junk: 'Transaction Summary'!$N$6
Name lbo.ltdebt: DebtSchedule!$J$22

Sheet Parms
A1: Legends Inc. | G1: {=_xlfn.SEQUENCE(1,8,2022,1)} -> 2022 | H1: 2023 | I1: 2024 | J1: 2025 | K1: 2026 | L1: 2027 | M1: 2028 | N1: 2029
B2: Revenues
C3: Foot Solutions | G3: 8399 | H3: 8791 | I3: 9200 | J3: =I3*(1+J7) -> 9628.7066 | K3: =J3*(1+K7) -> 10077.035 | L3: =K3*(1+L7) -> 10546.425 | M3: =L3*(1+M7) -> 11037.582 | N3: =M3*(1+N7) -> 11551.663
C4: Greeting Fulfillments | G4: 8696 | H4: 8800 | I4: 8850 | J4: =I4*(1+J8) -> 8928.0629 | K4: =J4*(1+K8) -> 8992.8025 | L4: =K4*(1+L8) -> 9065.0683 | M4: =L4*(1+M8) -> 9134.358 | N4: =M4*(1+N8) -> 9205.9694
C5: Legendwear | G5: 8366 | H5: 8657 | I5: 8900 | J5: =I5*(1+J9) -> 9179.6977 | K5: =J5*(1+K9) -> 9452.7776 | L5: =K5*(1+L9) -> 9741.9141 | M5: =L5*(1+M9) -> 10035.807 | N5: =M5*(1+N9) -> 10340.671
B6: % Change
C7: {=+C3:C5} -> Foot Solutions | H7: =+H3/G3-1 -> 0.046672223 | I7: =+I3/H3-1 -> 0.046524855 | J7: =AVERAGE(H7:I7) -> 0.046598539 | K7: =AVERAGE(I7:J7) -> 0.046561697 | L7: =AVERAGE(J7:K7) -> 0.046580118 | M7: =AVERAGE(K7:L7) -> 0.046570907 | N7: =AVERAGE(L7:M7) -> 0.046575513
C8: Greeting Fulfillments | H8: =+H4/G4-1 -> 0.011959522 | I8: =+I4/H4-1 -> 0.0056818182 | J8: =AVERAGE(H8:I8) -> 0.0088206699 | K8: =AVERAGE(I8:J8) -> 0.007251244 | L8: =AVERAGE(J8:K8) -> 0.008035957 | M8: =AVERAGE(K8:L8) -> 0.0076436005 | N8: =AVERAGE(L8:M8) -> 0.0078397787
C9: Legendwear | H9: =+H5/G5-1 -> 0.034783648 | I9: =+I5/H5-1 -> 0.02806977 | J9: =AVERAGE(H9:I9) -> 0.031426709 | K9: =AVERAGE(I9:J9) -> 0.02974824 | L9: =AVERAGE(J9:K9) -> 0.030587474 | M9: =AVERAGE(K9:L9) -> 0.030167857 | N9: =AVERAGE(L9:M9) -> 0.030377666
B10: Cost of Goods Sold
C11: {=+C3:C5} -> Foot Solutions | G11: 0.52854836 | H11: 0.51945532 | I11: 0.52962561 | J11: =AVERAGE(G11:I11) -> 0.52587643 | K11: =AVERAGE(H11:J11) -> 0.52498579 | L11: =AVERAGE(I11:K11) -> 0.52682928 | M11: =AVERAGE(J11:L11) -> 0.52589717 | N11: =AVERAGE(K11:M11) -> 0.52590408
C12: Greeting Fulfillments | G12: 0.54951212 | H12: 0.50621255 | I12: 0.54249378 | J12: =AVERAGE(G12:I12) -> 0.53273948 | K12: =AVERAGE(H12:J12) -> 0.5271486 | L12: =AVERAGE(I12:K12) -> 0.53412729 | M12: =AVERAGE(J12:L12) -> 0.53133846 | N12: =AVERAGE(K12:M12) -> 0.53087145
C13: Legendwear | G13: 0.50169648 | H13: 0.51854696 | I13: 0.53504035 | J13: =AVERAGE(G13:I13) -> 0.51842793 | K13: =AVERAGE(H13:J13) -> 0.52400508 | L13: =AVERAGE(I13:K13) -> 0.52582446 | M13: =AVERAGE(J13:L13) -> 0.52275249 | N13: =AVERAGE(K13:M13) -> 0.52419401
B14: Operating Expenses (aka fixed costs)
C15: Rent | G15: 0.04520141 | H15: 0.041519682 | I15: 0.041485585 | J15: =AVERAGE(G15:I15) -> 0.042735559 | K15: =AVERAGE(H15:J15) -> 0.041913609 | L15: =AVERAGE(I15:K15) -> 0.042044918 | M15: =AVERAGE(J15:L15) -> 0.042231362 | N15: =AVERAGE(K15:M15) -> 0.042063296
C16: Utilities | G16: 0.039664353 | H16: 0.04825251 | I16: 0.0428629 | J16: =AVERAGE(G16:I16) -> 0.043593254 | K16: =AVERAGE(H16:J16) -> 0.044902888 | L16: =AVERAGE(I16:K16) -> 0.043786347 | M16: =AVERAGE(J16:L16) -> 0.044094163 | N16: =AVERAGE(K16:M16) -> 0.044261133
C17: Phone | G17: 0.030733282 | H17: 0.037306794 | I17: 0.041556613 | J17: =AVERAGE(G17:I17) -> 0.03653223 | K17: =AVERAGE(H17:J17) -> 0.038465212 | L17: =AVERAGE(I17:K17) -> 0.038851352 | M17: =AVERAGE(J17:L17) -> 0.037949598 | N17: =AVERAGE(K17:M17) -> 0.038422054
C18: Advertising | G18: 0.031545546 | H18: 0.037579353 | I18: 0.036485053 | J18: =AVERAGE(G18:I18) -> 0.035203317 | K18: =AVERAGE(H18:J18) -> 0.036422575 | L18: =AVERAGE(I18:K18) -> 0.036036982 | M18: =AVERAGE(J18:L18) -> 0.035887625 | N18: =AVERAGE(K18:M18) -> 0.036115727
C19: Salaries | G19: 0.037692894 | H19: 0.046375124 | I19: 0.033670329 | J19: =AVERAGE(G19:I19) -> 0.039246116 | K19: =AVERAGE(H19:J19) -> 0.039763856 | L19: =AVERAGE(I19:K19) -> 0.0375601 | M19: =AVERAGE(J19:L19) -> 0.038856691 | N19: =AVERAGE(K19:M19) -> 0.038726882
C20: Depreciation Expense | G20: 1000 | H20: =+G20 -> 1000 | I20: =+H20 -> 1000 | J20: =+I20 -> 1000 | K20: =+J20 -> 1000 | L20: =+K20 -> 1000 | M20: =+L20 -> 1000 | N20: =+M20 -> 1000
C21: Amortization Expense | G21: 250 | H21: =+G21 -> 250 | I21: =+H21 -> 250 | J21: =I21+LBO.Goodwill/20 -> 2476.6997 | K21: =+J21 -> 2476.6997 | L21: =+K21 -> 2476.6997 | M21: =+L21 -> 2476.6997 | N21: =+M21 -> 2476.6997
B22: Tax Rate | G22: 0.21
B23: Cash Dividends | G23: 1500 | H23: =+G23 -> 1500 | I23: =+H23 -> 1500 | J23: 0 | K23: =+J23 -> 0 | L23: =+K23 -> 0 | M23: =+L23 -> 0 | N23: =+M23 -> 0
B24: Stock Buybacks | G24: 500 | H24: =+G24 -> 500 | I24: =+H24 -> 500 | J24: 0 | K24: =+J24 -> 0 | L24: =+K24 -> 0 | M24: =+L24 -> 0 | N24: =+M24 -> 0
B25: Balance Sheet
C26: Working Capital
D27: Accounts Receivable (days of Sales) | G27: 60 | H27: =+G27 -> 60 | I27: =+H27 -> 60 | J27: 58 | K27: 58 | L27: 56 | M27: 56 | N27: 54
D28: Inventory (days of COGS) | G28: 32 | H28: =+G28 -> 32 | I28: =+H28 -> 32 | J28: 30 | K28: 30 | L28: 28 | M28: 28 | N28: 26
D29: Prepaid Expenses | G29: 0.03 | H29: =+G29 -> 0.03 | I29: =+H29 -> 0.03 | J29: =+I29 -> 0.03 | K29: =+J29 -> 0.03 | L29: =+K29 -> 0.03 | M29: =+L29 -> 0.03 | N29: =+M29 -> 0.03
D30: Accounts Payable (days COGS) | G30: 35 | H30: =+G30 -> 35 | I30: =+H30 -> 35 | J30: =+I30 -> 35 | K30: 37 | L30: =+K30 -> 37 | M30: 39 | N30: =+M30 -> 39
D31: Accrued Liabilities | G31: 0.03 | H31: =+G31 -> 0.03 | I31: =+H31 -> 0.03 | J31: =+I31 -> 0.03 | K31: =+J31 -> 0.03 | L31: =+K31 -> 0.03 | M31: =+L31 -> 0.03 | N31: =+M31 -> 0.03
C32: Capital Expenditure (CAPEX) | H32: 2500 | I32: =+H32 -> 2500 | J32: 1750 | K32: =J32 -> 1750 | L32: 1500 | M32: =L32 -> 1500 | N32: =+M32 -> 1500
C33: Starting Gross PP&E | G33: 6000
C34: Starting Accumulated Depreciation | G34: 1500
C35: Starting.Goodwill | G35: 2000
C36: Starting Cash | G36: 4500

Sheet Transaction Summary
A1: Transaction Summary for Leveraged Buyout
B2: Valuation | I2: Sources and Uses of Deal Cash
C3: EBITDA | G3: =SUM(hist.amort,hist.depreciation,hist.EBIT) -> 7230.6853 | J3: Sources | N3: $ | O3: % | P3: xEBITDA | Q3: Fee % | R3: Fee $
C4: Market Multiple | G4: 8 | K4: Balance Sheet Cash | N4: =hist.cash -> 3992.7969 | O4: {=N4:N7/N8} -> 0.05576666 | P4: {=N4:N8/G3} -> 0.55220173
D5: Enterprise Value | G5: =G4*G3 -> 57845.482 | K5: Revolver (Senior Debt) | N5: 18000 | O5: 0.25140269 | P5: 2.4893906 | Q5: 0.03 | R5: =Q5*LBO.Revolver -> 540
D6: Capitalization | K6: Subordinated (Junk Bonds) | N6: 18000 | O6: 0.25140269 | P6: 2.4893906 | Q6: 0.04 | R6: =Q6*LBO.junk -> 720
E7: Less: | K7: Sponsor Equity (Gecko Fund) | N7: =30000+1605.48241990259 -> 31605.482 | O7: 0.44142796 | P7: 4.3710217
F8: Debt | G8: =-DCF.Debt -> -5500 | J8: Total Sources | N8: =SUM(N4:N7) -> 71598.279 | P8: 9.9020046 | R8: =SUM(R4:R7) -> 1260
F9: Preferred Stock | G9: =-DCF.Pref.Stock -> -1500
E10: Add: | J10: Uses
F11: Cash | G11: =hist.cash -> 3992.7969 | K11: Minimum Cash Balance | N11: =min.cash -> 5000 | O11: {=N11:N16/N17} -> 0.06983408
C12: Net Offer Value to Share Holders | G12: =SUM(G5:G11) -> 54838.279 | K12: Purchase of Equity | N12: =G12 -> 54838.279 | O12: 0.76591616
D13: Offer Per Share | G13: =G12/shares.outstanding -> 46.329575 | K13: Retire Debt | N13: =-G8 -> 5500 | O13: 0.076817489
K14: Retire Preferred Shares | N14: =-G9 -> 1500 | O14: 0.020950224
B15: Other Assumptions | K15: M&A Fee | N15: =goldman.fee -> 3500 | O15: 0.048883856
C16: Revolver EBITDA Borrowing Base Multiplier | G16: 6 | K16: Debt Placement Fee | N16: =PNC.fee -> 1260 | O16: 0.017598188
C17: Revolver Availability @ Close | G17: =G16*G3 -> 43384.112 | J17: Total Uses | N17: =SUM(N11:N16) -> 71598.279
C18: Minimum Cash Balance | G18: 5000
C19: Fee: Mergers & Acquisition | G19: =3500 -> 3500 | J19: Checksum | N19: =_xlfn.LET(_xlpm.sources,N8,_xlpm.uses,N17,_xlpm.sources-_xlpm.uses) -> 0
B21: Goodwill Calculation
C22: Purchase of Equity | G22: =G12 -> 54838.279
D23: Less: Book Value of Assets | G23: =-(DCF.Equity-DCF.Pref.Stock) -> -10304.286
C24: Goodwill | G24: =SUM(G22:G23) -> 44533.993

Sheet LBO Returns
A1: LBO Returns Calculation
B2: Weighted Average Cost of Capital
C3: Capital Stack | G3: {=dates.forecast} -> 2025 | H3: 2026 | I3: 2027 | J3: 2028 | K3: 2029
D4: Revolver | G4: {=Revolver} -> 15814.109 | H4: 13445.451 | I4: 10465.326 | J4: 7149.9307 | K4: 3304.3302
D5: Subordinated Debt | G5: {=Sub.Debt} -> 18000 | H5: 18000 | I5: 18000 | J5: 18000 | K5: 18000
D6: Gecko Fund Equity | G6: {=f.equity} -> 27543.858 | H6: 28485.938 | I6: 29802.369 | J6: 31561.748 | K6: 33750.904
C7: Total Capital | G7: =SUM(G4:G6) -> 61357.967 | H7: =SUM(H4:H6) -> 59931.389 | I7: =SUM(I4:I6) -> 58267.695 | J7: =SUM(J4:J6) -> 56711.679 | K7: =SUM(K4:K6) -> 55055.234
C8: Weights
D9: {=+D4:D6} -> Revolver | G9: {=G4:K6/G7:K7} -> 0.25773522 | H9: 0.22434739 | I9: 0.17960768 | J9: 0.1260751 | K9: 0.060018457
D10: Subordinated Debt | G10: 0.29336044 | H10: 0.30034345 | I10: 0.30891904 | J10: 0.31739494 | K10: 0.32694439
D11: Gecko Fund Equity | G11: 0.44890434 | H11: 0.47530916 | I11: 0.51147328 | J11: 0.55652996 | K11: 0.61303715
C12: After-Tax Cost of Each Capital Source
D13: {=D4:D6} -> Revolver | G13: {=rate.revolver*(1-tax.rate)} -> 0.06715 | H13: 0.06715 | I13: 0.06715 | J13: 0.06715 | K13: 0.06715
D14: Subordinated Debt | G14: {=rate.sub.debt*(1-tax.rate)} -> 0.0869 | H14: 0.0869 | I14: 0.0869 | J14: 0.0869 | K14: 0.0869
D15: Gecko Fund Equity | G15: 0.2371 | H15: =G15 -> 0.2371 | I15: =H15 -> 0.2371 | J15: =I15 -> 0.2371 | K15: =J15 -> 0.2371
C16: WACC | G16: =SUMPRODUCT(G9:G11,G13:G15) -> 0.14923516 | H16: =SUMPRODUCT(H9:H11,H13:H15) -> 0.15386058 | I16: =SUMPRODUCT(I9:I11,I13:I15) -> 0.16017604 | J16: =SUMPRODUCT(J9:J11,J13:J15) -> 0.16800082 | K16: =SUMPRODUCT(K9:K11,K13:K15) -> 0.17779282
C17: Discount Factors
D18: 1-Year Factors | G18: =1/(1+G16) -> 0.87014393 | H18: =1/(1+H16) -> 0.86665583 | I18: =1/(1+I16) -> 0.86193816 | J18: =1/(1+J16) -> 0.85616379 | K18: =1/(1+K16) -> 0.84904576
D19: Cumulative Discount | G19: =PRODUCT($G18:G18) -> 0.87014393 | H19: =PRODUCT($G18:H18) -> 0.75411531 | I19: =PRODUCT($G18:I18) -> 0.65000077 | J19: =PRODUCT($G18:J18) -> 0.55650712 | K19: =PRODUCT($G18:K18) -> 0.47250001
B21: Free Cash Flow Buildup | G21: {=dates.forecast} -> 2025 | H21: 2026 | I21: 2027 | J21: 2028 | K21: 2029
C22: EBITDA | G22: {=DCF.Table} -> 7684.9185 | H22: 7792.0701 | I22: 8012.6201 | J22: 8291.5061 | K22: 8508.6504
D23: Less: Depreciation and Amort | G23: -3476.6997 | H23: -3476.6997 | I23: -3476.6997 | J23: -3476.6997 | K23: -3476.6997
C24: EBIT | G24: 4208.2188 | H24: 4315.3704 | I24: 4535.9205 | J24: 4814.8065 | K24: 5031.9507
D25: Less: Income Tax | G25: -883.72595 | H25: -906.22779 | I25: -952.5433 | J25: -1011.1094 | K25: -1056.7097
C26: EBIAT | G26: 3324.4929 | H26: 3409.1426 | I26: 3583.3772 | J26: 3803.6971 | K26: 3975.2411
D27: Add back: Depr & Amort | G27: 3476.6997 | H27: 3476.6997 | I27: 3476.6997 | J27: 3476.6997 | K27: 3476.6997
D28: Change in Working Capital | G28: 103.76086 | H28: -37.265311 | I28: 124.15693 | J28: -34.468438 | K28: 137.95622
C29: Unlevered Cash from Operations | G29: 6904.9534 | H29: 6848.577 | I29: 7184.2338 | J29: 7245.9283 | K29: 7589.897
D30: Less: CAPEX | G30: -1750 | H30: -1750 | I30: -1500 | J30: -1500 | K30: -1500
C31: Unlevered Free Cash Flow | G31: 5154.9534 | H31: 5098.577 | I31: 5684.2338 | J31: 5745.9283 | K31: 6089.897
B33: Equity Calculations | H33: Terminal Values
G34: Exit Multiplier | H34: Enterprise Value | I34: Plus: Cash | J34: Less: Debt | K34: Residual Value
G35: {=_xlfn.SEQUENCE(4,1,8,2)} -> 8 | H35: {=Term.EBITDA*_xlfn.ANCHORARRAY(G35)} -> 68069.203 | I35: =Term.Cash -> 6887.3899 | J35: =-Term.Revolver-Term.Sub.Debt -> -21304.33 | K35: {=_xlfn.BYROW(H35:J38, _xlfn.LAMBDA(_xlpm.row, SUM(_xlpm.row)))} -> 53652.263
G36: 10 | H36: 85086.504 | I36: =Term.Cash -> 6887.3899 | J36: =-Term.Revolver-Term.Sub.Debt -> -21304.33 | K36: 70669.564
G37: 12 | H37: 102103.8 | I37: =Term.Cash -> 6887.3899 | J37: =-Term.Revolver-Term.Sub.Debt -> -21304.33 | K37: 87686.865
G38: 14 | H38: 119121.11 | I38: =Term.Cash -> 6887.3899 | J38: =-Term.Revolver-Term.Sub.Debt -> -21304.33 | K38: 104704.17
B40: Gecko's Performance
C41: Gecko Fund III Initial Investment | G41: =-LBO.equity -> -31605.482 | O41: Undiscounted FCF
G42: Exit Multiplier | H42: NPV | I42: IRR | N42: Exit Multiplier | O42: {=_xlfn.SEQUENCE(1,6,0)} -> 0 | P42: 1 | Q42: 2 | R42: 3 | S42: 4 | T42: 5
G43: {=_xlfn.SEQUENCE(4,1,8,2)} -> 8 | H43: =$G$41+SUMPRODUCT(P43:T43,LBO.Discount.Factors) -> 11845.562 | I43: {=_xlfn.BYROW(O43:T46, _xlfn.LAMBDA(_xlpm.row, IRR(_xlpm.row)))} -> 0.25621931 | N43: {=_xlfn.SEQUENCE(4,1,8,2)} -> 8 | O43: =$G$41 -> -31605.482 | P43: {=_xlfn.TAKE(LBO.Unlevered.FCF,1,4)} -> 5154.9534 | Q43: 5098.577 | R43: 5684.2338 | S43: 5745.9283 | T43: {=_xlfn.TAKE(LBO.Unlevered.FCF,1,-1)+_xlfn.ANCHORARRAY(K35)} -> 59742.16
...

Sheet Financial Statements
A1: =company.name&" Financial Statements" -> Legends Inc. Financial Statements
B2: Income Statement | G2: {=dates.hist} -> 2022 | H2: 2023 | I2: 2024 | J2: BUYOUT | K2: {=dates.forecast} -> 2025 | L2: 2026 | M2: 2027 | N2: 2028 | O2: 2029
C3: Revenues
D4: {=+Parms!C3:C5} -> Foot Solutions | G4: {=P.H.Revenues} -> 8399 | H4: 8791 | I4: 9200 | K4: {=P.F.REV} -> 9628.7066 | L4: 10077.035 | M4: 10546.425 | N4: 11037.582 | O4: 11551.663
D5: Greeting Fulfillments | G5: 8696 | H5: 8800 | I5: 8850 | K5: 8928.0629 | L5: 8992.8025 | M5: 9065.0683 | N5: 9134.358 | O5: 9205.9694
D6: Legendwear | G6: 8366 | H6: 8657 | I6: 8900 | K6: 9179.6977 | L6: 9452.7776 | M6: 9741.9141 | N6: 10035.807 | O6: 10340.671
C7: Total Revenues | G7: =SUM(G4:G6) -> 25461 | H7: =SUM(H4:H6) -> 26248 | I7: =SUM(I4:I6) -> 26950 | K7: =SUM(K4:K6) -> 27736.467 | L7: =SUM(L4:L6) -> 28522.616 | M7: =SUM(M4:M6) -> 29353.407 | N7: =SUM(N4:N6) -> 30207.746 | O7: =SUM(O4:O6) -> 31098.303
C9: Cost of Goods Sold
D10: {=+_xlfn.ANCHORARRAY(D4)} -> Foot Solutions | G10: {=P.H.COGS*P.H.Revenues} -> 4439.2777 | H10: 4566.5317 | I10: 4872.5556 | K10: {=P.F.REV*P.F.COGS} -> 5063.5098 | L10: 5290.3004 | M10: 5556.1654 | N10: 5804.6329 | O10: 6075.0664
D11: Greeting Fulfillments | G11: 4778.5574 | H11: 4454.6704 | I11: 4801.07 | K11: 4756.3316 | L11: 4740.5433 | M11: 4841.9003 | N11: 4853.4357 | O11: 4887.1863
D12: Legendwear | G12: 4197.1927 | H12: 4489.061 | I12: 4761.8592 | K12: 4759.0117 | L12: 4953.3035 | M12: 5122.5367 | N12: 5246.243 | O12: 5420.5179
C13: Total Cost of Goods Sold | G13: =SUM(G10:G12) -> 13415.028 | H13: =SUM(H10:H12) -> 13510.263 | I13: =SUM(I10:I12) -> 14435.485 | K13: =SUM(K10:K12) -> 14578.853 | L13: =SUM(L10:L12) -> 14984.147 | M13: =SUM(M10:M12) -> 15520.602 | N13: =SUM(N10:N12) -> 15904.312 | O13: =SUM(O10:O12) -> 16382.771
C15: Gross Margin | G15: {=H.Revenues-H.COGS} -> 12045.972 | H15: 12737.737 | I15: 12514.515 | K15: {=F.REV-F.COGS} -> 13157.614 | L15: 13538.468 | M15: 13832.805 | N15: 14303.435 | O15: 14715.533
D16: % Revenues | G16: {=H.Gross.Margin/H.Revenues} -> 0.47311465 | H16: 0.48528409 | I16: 0.46436049 | K16: {=F.MARGIN/F.REV} -> 0.47437959 | L16: 0.47465732 | M16: 0.4712504 | N16: 0.47350222 | O16: 0.47319407
C18: Selling, General and Administrative Expenses
D19: Rent | G19: {=H.Revenues*P.H.Fixed.Costs} -> 1150.8731 | H19: 1089.8086 | I19: 1118.0365 | K19: {=F.REV*P.F.FIXED.COST} -> 1185.3334 | L19: 1195.4857 | M19: 1234.1616 | N19: 1275.7143 | O19: 1308.0971
D20: Utilities | G20: 1009.8941 | H20: 1266.5319 | I20: 1155.1551 | K20: 1209.1229 | L20: 1280.7478 | M20: 1285.2785 | N20: 1331.9853 | O20: 1376.4461
D21: Phone | G21: 782.5001 | H21: 979.22872 | I21: 1119.9507 | K21: 1013.275 | L21: 1097.1285 | M21: 1140.4196 | N21: 1146.3718 | O21: 1194.8607
D22: Advertising | G22: 803.18113 | H22: 986.38287 | I22: 983.27219 | K22: 976.41566 | L22: 1038.8671 | M22: 1057.8082 | N22: 1084.0843 | O22: 1123.1378
D23: Salaries | G23: 959.69878 | H23: 1217.2543 | I23: 907.41536 | K23: 1088.5486 | L23: 1134.1692 | M23: 1102.5169 | N23: 1173.7731 | O23: 1204.3403
D24: Depreciation Expense | G24: {=P.H.Depreciation.Expense} -> 1000 | H24: 1000 | I24: 1000 | K24: {=P.F.DEPREC} -> 1000 | L24: 1000 | M24: 1000 | N24: 1000 | O24: 1000
D25: Amortization Expense | G25: {=P.H.Amortization.Expense} -> 250 | H25: 250 | I25: 250 | K25: {=P.F.AMORT} -> 2476.6997 | L25: 2476.6997 | M25: 2476.6997 | N25: 2476.6997 | O25: 2476.6997
C26: Total SG&A Expenses | G26: =SUM(G19:G25) -> 5956.1472 | H26: =SUM(H19:H25) -> 6789.2064 | I26: =SUM(I19:I25) -> 6533.8299 | K26: =SUM(K19:K25) -> 8949.3952 | L26: =SUM(L19:L25) -> 9223.098 | M26: =SUM(M19:M25) -> 9296.8844 | N26: =SUM(N19:N25) -> 9488.6284 | O26: =SUM(O19:O25) -> 9683.5818
C28: Earnings Before Interest and Taxes (EBIT) | G28: {=H.Gross.Margin-H.Fixed.Costs} -> 6089.825 | H28: 5948.5305 | I28: 5980.6853 | K28: {=F.MARGIN-F.FIXED.COSTS} -> 4208.2188 | L28: 4315.3704 | M28: 4535.9205 | N28: 4814.8065 | O28: 5031.9507
D29: % Revenues | G29: {=H.Operating.Income/H.Revenues} -> 0.23918248 | H29: 0.22662795 | I29: 0.22191782 | K29: {=F.EBIT/F.REV} -> 0.15172152 | L29: 0.15129645 | M29: 0.1545279 | N29: 0.15938979 | O29: 0.16180789
C31: Interest Expense | G31: {=D.H.Interest.Expense} -> 525.5 | H31: 509.375 | I31: 370.25 | K31: {=D.F.INTEREST} -> 3324.1993 | L31: 3122.8633 | M31: 2869.5527 | N31: 2587.7441 | O31: 2260.8681
C33: Earnings Before Taxes (EBT) | G33: {=H.EBIT-G31:I31} -> 5564.325 | H33: 5439.1555 | I33: 5610.4353 | K33: =K28-K31 -> 884.01954 | L33: =L28-L31 -> 1192.5071 | M33: =M28-M31 -> 1666.3678 | N33: =N28-N31 -> 2227.0623 | O33: =O28-O31 -> 2771.0827
C35: Income Tax Expense | G35: {=+_xlfn.ANCHORARRAY(G33)*tax.rate} -> 1168.5082 | H35: 1142.2227 | I35: 1178.1914 | K35: =K33*tax.rate -> 185.6441 | L35: =L33*tax.rate -> 250.42649 | M35: =M33*tax.rate -> 349.93724 | N35: =N33*tax.rate -> 467.68309 | O35: =O33*tax.rate -> 581.92736
C37: Net Income | G37: {=+_xlfn.ANCHORARRAY(G33)-_xlfn.ANCHORARRAY(G35)} -> 4395.8167 | H37: 4296.9328 | I37: 4432.2439 | K37: =K33-K35 -> 698.37543 | L37: =L33-L35 -> 942.08059 | M37: =M33-M35 -> 1316.4306 | N37: =N33-N35 -> 1759.3793 | O37: =O33-O35 -> 2189.1553
C39: Less: Cash Dividends | G39: {=-P.H.Dividends} -> -1500 | H39: -1500 | I39: -1500 | K39: {=-P.F.DIV} -> 0 | L39: 0 | M39: 0 | N39: 0 | O39: 0
C40: Change in Retained Earnings | G40: {=+_xlfn.ANCHORARRAY(G37)+_xlfn.ANCHORARRAY(G39)} -> 2895.8167 | H40: 2796.9328 | I40: 2932.2439 | K40: =+K37+K39 -> 698.37543 | L40: =+L37+L39 -> 942.08059 | M40: =+M37+M39 -> 1316.4306 | N40: =+N37+N39 -> 1759.3793 | O40: =+O37+O39 -> 2189.1553
B43: Balance Sheet | G43: {=dates.hist} -> 2022 | H43: 2023 | I43: 2024 | J43: BUYOUT | K43: {=dates.forecast} -> 2025 | L43: 2026 | M43: 2027 | N43: 2028 | O43: 2029
C44: Assets
D45: Short Term Assets
E46: Cash | G46: {=H.Cash} -> 4500 | H46: 5168.3457 | I46: 3992.7969 | J46: =min.cash -> 5000 | K46: {=f.cash} -> 5342.9453 | L46: 5605.8019 | M46: 6042.9636 | N46: 6429.1792 | O46: 6887.3899
E47: Accounts Receivable | G47: {=H.Revenues*(P.H.Accounts.Rec.Days/365)} -> 4185.3699 | H47: 4314.7397 | I47: 4430.137 | J47: =+I47 -> 4430.137 | K47: {=F.REV*(p.f.rec.days/365)} -> 4407.4386 | L47: 4532.3608 | M47: 4503.5365 | N47: 4634.6131 | O47: 4600.8449
E48: Inventory | G48: {=H.COGS*(P.H.Inventory.Days/365)} -> 1176.112 | H48: 1184.4614 | I48: 1265.5767 | J48: =+I48 -> 1265.5767 | K48: {=F.COGS*(p.f.invent.cogs/365)} -> 1198.2619 | L48: 1231.5737 | M48: 1190.6216 | N48: 1220.0568 | O48: 1166.9919
E49: Prepaid Expenses | G49: {=P.H.Prepaids*H.Revenues} -> 763.83 | H49: 787.44 | I49: 808.5 | J49: =+I49 -> 808.5 | K49: {=p.f.prepaid*F.REV} -> 832.09402 | L49: 855.67847 | M49: 880.60222 | N49: 906.23239 | O49: 932.94909
D50: Total Short Term Assets | G50: =SUM(G46:G49) -> 10625.312 | H50: =SUM(H46:H49) -> 11454.987 | I50: =SUM(I46:I49) -> 10497.011 | J50: =SUM(J46:J49) -> 11504.214 | K50: =SUM(K46:K49) -> 11780.74 | L50: =SUM(L46:L49) -> 12225.415 | M50: =SUM(M46:M49) -> 12617.724 | N50: =SUM(N46:N49) -> 13190.082 | O50: =SUM(O46:O49) -> 13588.176
D52: Long Term Assets
...

Sheet DCF Model
A1: =+"Discount Cash Flow Model for "&company.name -> Discount Cash Flow Model for Legends Inc.
A2: General Assumptions
C3: Share Price | G3: {=_FV(H3,"Price")} -> 24.25 | H3: #VALUE!
C4: Shares Outstanding | G4: {=+_FV(H3,"Shares outstanding",TRUE)/1000000} -> 1183.656
C5: Market Capitalization | G5: {=+_FV(H3,"Market cap",TRUE)/1000000000} -> 28.703658
A7: Weighted Average Cost of Capital | G7: Amount | H7: Weight | I7: Cost
C8: Debt | G8: =DCF.Debt -> 5500 | H8: =+G8/$G$11 -> 0.31784033 | I8: =(DCF.Interest.Expense/G8)*(100%-tax.rate) -> 0.053181364
C9: Preffered Stock | G9: =+DCF.Pref.Stock -> 1500 | H9: =+G9/$G$11 -> 0.086683726 | I9: 0.0787
C10: Common Stock | G10: =+DCF.Equity-G9 -> 10304.286 | H10: =+G10/$G$11 -> 0.59547594 | I10: 0.1883
G11: =SUM(G8:G10) -> 17304.286
B12: WACC | G12: =SUMPRODUCT(H8:H10,I8:I10) -> 0.13585331
A13: Operating Forecast & Free Cash Flow Assumptions
B14: Free Cash Flow Buildup | G14: {=dates.forecast} -> 2025 | H14: 2026 | I14: 2027 | J14: 2028 | K14: 2029
C15: EBITDA | G15: {=F.EBIT+P.F.AMORT+P.F.DEPREC} -> 7684.9185 | H15: 7792.0701 | I15: 8012.6201 | J15: 8291.5061 | K15: 8508.6504
D16: Less: Depreciation and Amort | G16: {=-P.F.DEPREC-P.F.AMORT} -> -3476.6997 | H16: -3476.6997 | I16: -3476.6997 | J16: -3476.6997 | K16: -3476.6997
C17: EBIT | G17: {=F.EBIT} -> 4208.2188 | H17: 4315.3704 | I17: 4535.9205 | J17: 4814.8065 | K17: 5031.9507
D18: Less: Income Tax | G18: {=-_xlfn.ANCHORARRAY(G17)*tax.rate} -> -883.72595 | H18: -906.22779 | I18: -952.5433 | J18: -1011.1094 | K18: -1056.7097
C19: EBIAT | G19: {=+_xlfn.ANCHORARRAY(G17)+_xlfn.ANCHORARRAY(G18)} -> 3324.4929 | H19: 3409.1426 | I19: 3583.3772 | J19: 3803.6971 | K19: 3975.2411
D20: Add back: Depr & Amort | G20: {=-_xlfn.ANCHORARRAY(G16)} -> 3476.6997 | H20: 3476.6997 | I20: 3476.6997 | J20: 3476.6997 | K20: 3476.6997
D21: Change in Working Capital | G21: =+SUM('Financial Statements'!K96:K100) -> 103.76086 | H21: =+SUM('Financial Statements'!L96:L100) -> -37.265311 | I21: =+SUM('Financial Statements'!M96:M100) -> 124.15693 | J21: =+SUM('Financial Statements'!N96:N100) -> -34.468438 | K21: =+SUM('Financial Statements'!O96:O100) -> 137.95622
C22: Unlevered Cash from Operations | G22: =SUM(G19:G21) -> 6904.9534 | H22: =SUM(H19:H21) -> 6848.577 | I22: =SUM(I19:I21) -> 7184.2338 | J22: =SUM(J19:J21) -> 7245.9283 | K22: =SUM(K19:K21) -> 7589.897
D23: Less: CAPEX | G23: {=-p.f.capex} -> -1750 | H23: -1750 | I23: -1500 | J23: -1500 | K23: -1500
C24: Unlevered Free Cash Flow | G24: =SUM(G22:G23) -> 5154.9534 | H24: =SUM(H22:H23) -> 5098.577 | I24: =SUM(I22:I23) -> 5684.2338 | J24: =SUM(J22:J23) -> 5745.9283 | K24: =SUM(K22:K23) -> 6089.897
D25: Discount Factor | G25: {=1/(1+wacc)^G100} -> 0.88039537 | H25: {=1/(1+wacc)^H100} -> 0.77509601 | I25: {=1/(1+wacc)^I100} -> 0.68239094 | J25: {=1/(1+wacc)^J100} -> 0.60077383 | K25: {=1/(1+wacc)^K100} -> 0.5289185
C26: Discounted Free Cash Flow | G26: {=+G24:K24*G25:K25} -> 4538.3971 | H26: 3951.8867 | I26: 3878.8696 | J26: 3452.0034 | K26: 3221.0592
C27: Net Present Value | G27: =SUM(_xlfn.ANCHORARRAY(G26)) -> 19042.216
B29: Terminal Enterprise Valuations
C30: Perpetuity Approach
D31: Unlevered FCF Year 5 | G31: =dcf.fcf.y5 -> 6089.897
D32: Long Term Growth Rate | G32: 0.0383
D33: Forecast Year 6 FCF | G33: =G31*(1+G32) -> 6323.14
C34: Terminal Enterprise Value | G34: =+G33/(wacc-G32) -> 64817.277
C35: NPV Calculation
D36: PV of the Terminal Value | G36: =+G34*dcf.terminaldc -> 34283.057
D37: PV of the Free Cash Flows | G37: =+G27 -> 19042.216
C38: Total Enterprise Value | G38: =SUM(G36:G37) -> 53325.273
D39: Implied Terminal Value Exit Multiplier | G39: =+tv.gordon/dcf.terminal.ebitda -> 6.2671834
C41: Exit EBITDA Multiple Approach
D42: Terminal Value
E43: EBITDA Year 5 | G43: =dcf.terminal.ebitda -> 8508.6504
...

Sheet DebtSchedule
A1: =company.name&" Debt Schedule" -> Legends Inc. Debt Schedule
G2: {=dates.hist} -> 2022 | H2: 2023 | I2: 2024 | J2: BUYOUT | K2: {=dates.forecast} -> 2025 | L2: 2026 | M2: 2027 | N2: 2028 | O2: 2029
B3: Debt
C4: Huntington | G4: 2000 | H4: 1750 | I4: 1500 | K4: 0 | L4: =+K4 -> 0 | M4: =+L4 -> 0 | N4: =+M4 -> 0 | O4: =+N4 -> 0 | P4: =+O4 -> 0
C5: PNC | G5: 2500 | H5: =+G5 -> 2500 | I5: =+H5 -> 2500 | K5: =0 -> 0 | L5: =0 -> 0 | M5: =0 -> 0 | N5: =0 -> 0 | O5: =0 -> 0 | P5: =0 -> 0
C6: Keybank | G6: 3500 | H6: 3500 | I6: 1500 | K6: =0 -> 0 | L6: =+K6 -> 0 | M6: =+L6 -> 0 | N6: =+M6 -> 0 | O6: =+N6 -> 0 | P6: =+O6 -> 0
C7: Revolver | G7: 0 | H7: 0 | I7: 0 | J7: =LBO.Revolver -> 18000 | K7: =J7+K26+K27 -> 15814.109 | L7: =K7+L26+L27 -> 13445.451 | M7: =L7+M26+M27 -> 10465.326 | N7: =M7+N26+N27 -> 7149.9307 | O7: =N7+O26+O27 -> 3304.3302 | P7: =O7+P26+P27 -> 1804.3302
C8: Subordinated Debt | G8: 0 | H8: 0 | I8: 0 | J8: =LBO.junk -> 18000 | K8: =LBO.junk -> 18000 | L8: =LBO.junk -> 18000 | M8: =LBO.junk -> 18000 | N8: =LBO.junk -> 18000 | O8: =LBO.junk -> 18000 | P8: =LBO.junk -> 18000
B9: Total Debt | G9: =SUM(G4:G8) -> 8000 | H9: =SUM(H4:H8) -> 7750 | I9: =SUM(I4:I8) -> 5500 | J9: =SUM(J4:J8) -> 36000 | K9: =SUM(K4:K8) -> 33814.109 | L9: =SUM(L4:L8) -> 31445.451 | M9: =SUM(M4:M8) -> 28465.326 | N9: =SUM(N4:N8) -> 25149.931 | ... P9: =SUM(P4:P8) -> 19804.33
I10: DCF.Debt
B11: Interest Rate
C12: {=+C4:C8} -> Huntington | G12: 0.0645 | H12: =+G12 -> 0.0645 | I12: =+H12 -> 0.0645 | K12: =+I12 -> 0.0645 | L12: =+K12 -> 0.0645 | M12: =+L12 -> 0.0645 | N12: =+M12 -> 0.0645 | O12: =+N12 -> 0.0645
C13: PNC | G13: 0.0725 | H13: =+G13 -> 0.0725 | I13: =+H13 -> 0.0725 | K13: =+I13 -> 0.0725 | L13: =+K13 -> 0.0725 | M13: =+L13 -> 0.0725 | N13: =+M13 -> 0.0725 | O13: =+N13 -> 0.0725
C14: Keybank | G14: 0.0615 | H14: =+G14 -> 0.0615 | I14: =+H14 -> 0.0615 | K14: =+I14 -> 0.0615 | L14: =+K14 -> 0.0615 | M14: =+L14 -> 0.0615 | N14: =+M14 -> 0.0615 | O14: =+N14 -> 0.0615
C15: Revolver | G15: 0 | H15: =+G15 -> 0 | I15: =+H15 -> 0 | K15: 0.085 | L15: =+K15 -> 0.085 | M15: =+L15 -> 0.085 | N15: =+M15 -> 0.085 | O15: =+N15 -> 0.085
C16: Subordinated Debt | G16: 0 | H16: =+G16 -> 0 | I16: =+H16 -> 0 | K16: 0.11 | L16: =+K16 -> 0.11 | M16: =+L16 -> 0.11 | N16: =+M16 -> 0.11 | O16: =+N16 -> 0.11
B18: Interest Expense | G18: =SUMPRODUCT(G4:G8,G12:G16) -> 525.5 | H18: =SUMPRODUCT(H4:H8,H12:H16) -> 509.375 | I18: =SUMPRODUCT(I4:I8,I12:I16) -> 370.25 | K18: =SUMPRODUCT(K4:K8,K12:K16) -> 3324.1993 | L18: =SUMPRODUCT(L4:L8,L12:L16) -> 3122.8633 | M18: =SUMPRODUCT(M4:M8,M12:M16) -> 2869.5527 | N18: =SUMPRODUCT(N4:N8,N12:N16) -> 2587.7441 | O18: =SUMPRODUCT(O4:O8,O12:O16) -> 2260.8681
B20: Calc Current Portion of LT Debt
C21: Current Portion | G21: =+G9-H9 -> 250 | H21: =+H9-I9 -> 2250 | I21: 900 | J21: =J9-K9 -> 2185.8906 | K21: =K9-L9 -> 2368.6584 | L21: =L9-M9 -> 2980.1254 | M21: =M9-N9 -> 3315.3949 | N21: =N9-O9 -> 3845.6005 | O21: =O9-P9 -> 1500
C22: Long Term Debt | G22: =+G9-G21 -> 7750 | H22: =+H9-H21 -> 5500 | I22: =+I9-I21 -> 4600 | J22: =+J9-J21 -> 33814.109 | K22: =+K9-K21 -> 31445.451 | L22: =+L9-L21 -> 28465.326 | M22: =+M9-M21 -> 25149.931 | N22: =+N9-N21 -> 21304.33 | O22: =+O9-O21 -> 19804.33
B24: Revolver Paydown
C25: Paydown Amounts
D26: Mandatory | K26: =-1500 -> -1500 | L26: =-1500 -> -1500 | M26: =-1500 -> -1500 | N26: =-1500 -> -1500 | O26: =-1500 -> -1500 | P26: =-1500 -> -1500
D27: Variable | K27: {=variable.paydown} -> -685.89064 | L27: -868.6584 | M27: -1480.1254 | N27: -1815.3949 | O27: -2345.6005
B29: Revolver Discretionary Paydown Calculation
C30: Levered Free Cash Flow
D31: Net Income | K31: {=f.net.income} -> 698.37543 | L31: 942.08059 | M31: 1316.4306 | N31: 1759.3793 | O31: 2189.1553
D32: Add Back
E33: Depreciation | K33: {=P.F.DEPREC} -> 1000 | L33: 1000 | M33: 1000 | N33: 1000 | O33: 1000
E34: Amortization | K34: {=P.F.AMORT} -> 2476.6997 | L34: 2476.6997 | M34: 2476.6997 | N34: 2476.6997 | O34: 2476.6997
D35: Non-Cash Interest (PIK Debt) | K35: 0 | L35: =K35 -> 0 | M35: =L35 -> 0 | N35: =M35 -> 0 | O35: =N35 -> 0
D36: Change in Working Capital | K36: {=F.delta.working.capital} -> 103.76086 | L36: -37.265311 | M36: 124.15693 | N36: -34.468438 | O36: 137.95622
D37: CAPEX | K37: {=-p.f.capex} -> -1750 | L37: -1750 | M37: -1500 | N37: -1500 | O37: -1500
C38: Net Levered Free Cash Flow | K38: =SUM(K31:K37) -> 2528.836 | L38: =SUM(L31:L37) -> 2631.5149 | M38: =SUM(M31:M37) -> 3417.2871 | N38: =SUM(N31:N37) -> 3701.6105 | O38: =SUM(O31:O37) -> 4303.8112
C40: Beginning Cash Balance | K40: {=f.cash} -> 5342.9453 | L40: 5605.8019 | M40: 6042.9636 | N40: 6429.1792 | O40: 6887.3899
D41: Less: Minimum Cash Balance | K41: =-min.cash -> -5000 | L41: =-min.cash -> -5000 | M41: =-min.cash -> -5000 | N41: =-min.cash -> -5000 | O41: =-min.cash -> -5000
D42: Plus: Levered Free Cash Flow | K42: =K38 -> 2528.836 | L42: =L38 -> 2631.5149 | M42: =M38 -> 3417.2871 | N42: =N38 -> 3701.6105 | O42: =O38 -> 4303.8112
E43: LFCF Before Scheduled Paydown | K43: =SUM(K40:K42) -> 2871.7813 | L43: =SUM(L40:L42) -> 3237.3168 | M43: =SUM(M40:M42) -> 4460.2508 | N43: =SUM(N40:N42) -> 5130.7897 | O43: =SUM(O40:O42) -> 6191.2011
F44: Less: Scheduled Paydown | K44: =K26 -> -1500 | L44: =L26 -> -1500 | M44: =M26 -> -1500 | N44: =N26 -> -1500 | O44: =O26 -> -1500
E45: LFCF After Scheduled Paydown | K45: =SUM(K43:K44) -> 1371.7813 | L45: =SUM(L43:L44) -> 1737.3168 | M45: =SUM(M43:M44) -> 2960.2508 | N45: =SUM(N43:N44) -> 3630.7897 | O45: =SUM(O43:O44) -> 4691.2011
...
